Workbook

Sheet Tests
A1: Recette VERIFLOW : PR 17 à 41 (build de la branche claude/recette, Windows 11)
A2: Remplir uniquement les colonnes jaunes (Effectué, Résultat, Date, Commentaires). Mode d'emploi : onglet Légende.
A4: N° | B4: Section | C4: PR | D4: Action | E4: Résultat attendu | F4: Effectué | G4: Résultat | H4: Date | I4: Commentaires | J4: Réponse de Claude (mise à jour 27/10)
A5: 1 | B5: A. Installation et menus | C5: 37 | D5: Lancer setup.exe (build claude/recette, artefact veriflow-windows-latest). | E5: L'installeur affiche le CLUF en français avant l'installation. | F5: Oui | G5: OK | H5: 46317 | I5: RAS
A6: 2 | B6: A. Installation et menus | C6: 37 | D6: Aide > À propos. | E6: Version de FFmpeg (9.0.2) et bouton « Licences, CLUF et CGU » affichés. | F6: Oui | G6: OK | H6: 46317 | I6: RAS
A7: 3 | B7: A. Installation et menus | C7: 37 | D7: Cliquer sur « Licences, CLUF et CGU », ouvrir chaque rubrique. | E7: VERIFLOW, CLUF, CGU, FFmpeg (version et configuration), Composants tiers et Textes des licences ont tous un texte. | F7: Oui | G7: OK | H7: 46317 | I7: RAS
A8: 4 | B8: A. Installation et menus | C8: 26 | D8: Appuyer sur F1, changer de chapitre dans le sommaire. Relire le fond. | E8: Le guide s'ouvre, le sommaire change de chapitre. Remarques de fond dans Commentaires. | F8: Oui | G8: Partiel | H8: 46321 | I8: Ajouter des images du logiciel avec mise en avant des points mentionnés dans la version html dispo dans le logiciel + au lancement de Veriflow, l'application s'ouvre à chaque en mode fenêtre, il faut qu'elle s'ouvre par défaut fenêtre ajustée à la taille de l'écran et retienne le réglage si l'utilisateur laisse ainsi et ferme ou s'il l'a laissé en mode fenêtre. | J8: Fenêtre agrandie au premier lancement, taille et état retenus : fait, voir test 39 (build du 27/10 (run 40517638115)). Captures dans le guide : à faire (PR à venir).
A9: 5 | B9: A. Installation et menus | C9: 25 | D9: Préférences > Raccourcis : passer « Nouveau projet » en Ctrl+Maj+N ; donner Ctrl+S à « Ouvrir » ; puis « Tout rétablir ». | E9: Nouveau raccourci affiché dans le menu Fichier et actif ; message « Ctrl+S retiré de Enregistrer » ; défauts rétablis. | F9: Oui | G9: OK | H9: 46317 | I9: RAS
A10: 6 | B10: A. Installation et menus | C10: 25 | D10: Changer les valeurs des onglets OFFLOAD, PLAYER, TRANSCODE des Préférences, puis Général > « Remettre à zéro maintenant ». | E10: Les onglets de travail reprennent les valeurs des Préférences. | F10: Oui | G10: OK | H10: 46317 | I10: RAS | J10: Corrigé : bouton « Valider » (applique tout de suite aux onglets et lecteurs ouverts), « Annuler », « Valeurs d'usine » par rubrique. « Remettre à zéro maintenant » renommé « Vider l'état de travail » : il vide les destinations et dossiers en cours, pas les Préférences. À refaire dans le nouveau build.
A11: 7 | B11: B. OFFLOAD | C11: 21 | D11: Brancher le disque externe USB. | E11: Le disque apparaît comme amovible dans l'explorateur. | F11: Oui | G11: OK | H11: 46317 | I11: RAS
A12: 8 | B12: B. OFFLOAD | C12: 32 | D12: Bloc « Rapport PDF » : choisir un logo (PNG transparent si possible), laisser « Vignettes des vidéos » cochée. | E12: Réglages acceptés et mémorisés. | F12: Oui | G12: OK | H12: 46317 | I12: RAS
A13: 9 | B13: B. OFFLOAD | C13: 33 | D13: Cocher « Horodatage certifié RFC 3161 » (PC connecté à Internet). | E13: Option cochée, adresse DigiCert proposée. | F13: Oui | G13: OK | H13: 46317 | I13: RAS
A14: 10 | B14: B. OFFLOAD | C14: 31 | D14: Reconnaissance de carte : choisir comme source un dossier qui a gardé la structure d'une carte caméra (dossier PRIVATE/M4ROOT de Sony, fichiers .R3D de RED, clips A001C001... d'ARRI). Puis modèle d'arborescence {date}/{camera}/{bobine} et lecture de l'aperçu du chemin. | E14: Sous la source : « Carte reconnue : <type>, bobine <nom> ». L'aperçu du chemin reprend la lettre de caméra et la bobine. Sans structure de carte : rien d'affiché, {bobine} prend le nom du dossier. | F14: Oui | G14: OK | H14: 46318 | I14: RAS | J14: Test reformulé (colonne Action) : il vérifie que VERIFLOW reconnaît le type de carte d'après ses dossiers. Sans carte caméra, ou sans dossier qui a gardé la structure d'origine, marque « Non testable » et vérifie seulement l'aperçu du chemin.
A15: 11 | B15: B. OFFLOAD | C15: 21, 31, 32, 33 | D15: Copier un dossier de rushes vers le disque interne, « Éjecter la source après la copie » cochée. | E15: Dossier créé conforme à l'aperçu ; PDF avec logo et vignettes ; date certifiée sur la carte de la copie et fichier .pdf.tsr à côté du PDF ; « Source éjectée » sans fermer VERIFLOW. | F15: Oui | G15: OK | H15: 46317 | I15: Dans l'explorer de Veriflow, il y a un icone "ejecter" à côté des disques externes, cartes…etc, il faudrait que cet icône permette aussi d'éjecter ces supports en toute sécurité | J15: Bouton ⏏ de l'explorateur : fait, voir test 30 (build du 24/10 (run 40104706786)).
A16: 12 | B16: B. OFFLOAD | C16: 33 | D16: Rebrancher le disque, couper le Wi-Fi, refaire une petite copie. | E16: Rapports écrits ; « Horodatage impossible » affiché avec la cause. | F16: Oui | G16: OK | H16: 46317 | I16: RAS
A17: 13 | B17: B. OFFLOAD | C17: 21 | D17: Refaire une copie avec un fichier de la source ouvert dans un autre logiciel. | E17: Message « encore utilisé par un autre programme » ; le disque reste visible. | F17: Oui | G17: OK | H17: 46317 | I17: RAS | J17: À refaire après le test 11.
A18: 14 | B18: C. MEDIA et second écran | C18: 35 | D18: Double-clic sur un rush vidéo ; glisser la fenêtre sur la TV, la redimensionner ; Échap ; rouvrir. | E18: Vraie fenêtre système ; elle revient sur la TV, à la même taille. | F18: Oui | G18: OK | H18: 46321 | I18: Fenêtre glissée sur le 2e écran, double clic dans la barre du haut pour adapter à la taille de l'écran (pas en plein écran, juste fenêtre adaptée). Echap, ferme le lecteur pop-up. Double clic sur le même rush, le lecteur pop-up se rouvre sur le 1er écran, pas sur le 2e | J18: Corrigé : place mémorisée en pixels réels et fenêtre agrandie rétablie sur le même écran. À refaire avec le build du 24/10 (run 40104706786).
A19: 15 | B19: C. MEDIA et second écran | C19: 35 | D19: Double-clic sur un autre rush pendant que la fenêtre est ouverte. | E19: La même fenêtre recharge le nouveau rush. | F19: Oui | G19: OK | H19: 46319 | I19: Même protocole, pas en plein écran, juste fenêtre adaptée, la fenêtre reste bien en place et lance le 2e rush
A20: 16 | B20: C. MEDIA et second écran | C20: 35, 17 | D20: Sortie moniteur sur la TV depuis le lecteur rapide ; bouger puis immobiliser la souris sur la TV ; puis sortie moniteur depuis le PLAYER. | E20: Curseur masqué après 2 s d'immobilité, visible dès qu'il bouge ; un seul lecteur alimente la TV. | F20: Oui | G20: Partiel | H20: 46321 | I20: Lecteur pop-up déplacé sur le 2e écran, sortie TV choisie, affichage plein écran. Curseur souris disparait au bout de 2 sec et réapparait si je le bouge, mais pas de contrôle de lecture possible avec espace : ne fonctionne que quand le lecteur n'est pas en plein écran. | J20: Corrigé : après l'ouverture du moniteur, le clavier revient au lecteur (un clic sur le moniteur le lui donne, Échap le ferme). À refaire avec le build du 27/10 (run 40517638115).
A21: 17 | B21: C. MEDIA et second écran | C21: 35 | D21: Débrancher la TV, rouvrir le lecteur rapide. | E21: La fenêtre s'ouvre au centre de l'écran du portable. | F21: Oui | G21: Partiel | H21: 46321 | I21: Lecteur pop-up ouvert sur le 2e écran. Je débranche le 2e écran, le lecteur revient sur l'écran principal. Je ferme le lecteur pop-up, je double clic sur un rush, le lecteur pop-up s'ouvre sur l'écran principal (toujours pas de 2e écran branché) mais message d'erreur audio (voir capture) | J21: Cause trouvée : la sortie « par défaut du système » de Windows refuse le mode COM choisi par la bibliothèque audio. Les fils audio passent en mode multithread avant elle. À refaire avec le build du 27/10 (run 40517638115).
A22: 18 | B22: C. MEDIA et second écran | C22: 34 | D22: Seulement avec un WAV de plus de 4 Go : modifier la scène ou un nom de piste, faire la copie de travail, l'ouvrir dans Reaper, Resolve ou Pro Tools. | E22: Durée, pistes et métadonnées justes. | F22: Oui | G22: Partiel | H22: 46321 | I22: Double clic sur un media audio ouvre le player pop-up mais demande de charger un media (voir capture). | J22: Même cause que le test 17 : le son ne s'ouvrait pas, et la vue restait vide. L'erreur éventuelle s'affiche maintenant dans la vue. À refaire avec le build du 27/10 (run 40517638115).
A23: 19 | B23: D. PLAYER | C23: 30 | D23: Vidéo de smartphone avec un clap : lecture depuis le début, puis après un saut au milieu. | E23: Son synchrone dans les deux cas. | F23: Non
A24: 20 | B24: D. PLAYER | C24: 29 | D24: 1. Préférences > PLAYER : cocher « Ouvrir la saisie du rapport à chaque nouvelle prise », puis Valider. 2. Ouvrir un projet. 3. Dans MEDIA, ouvrir un clip dans le PLAYER. 4. Fermer la saisie (Échap), ouvrir un AUTRE clip dans le PLAYER. 5. Rouvrir le MÊME clip. | E24: Étape 3 et 4 : la fenêtre de saisie du rapport (touche R) s'ouvre seule. Étape 5 : elle ne s'ouvre pas. | F24: Oui | G24: OK | H24: 46321 | I24: Fonctionnel mais je ne comprends pas l'utilité. Il serait plus intéressant de pouvoir avoir accès aussi à l'explorer sur la gauche de l'application comme dans OFFLOAD et MEDIA. | J24: Utilité : en visionnant les prises une à une, la ligne du rapport s'ouvre seule, sans appuyer sur R. Explorateur à gauche dans le PLAYER : noté, à faire avec la liste de lecture (PR à venir).
A25: 21 | B25: D. PLAYER | C25: 5 (en attente) | D25: Ouvrir un rush vidéo avec du LTC sur une piste audio. | E25: Piste LTC coupée ; trois choix proposés : laisser coupée, baisser de 30 dB, réactiver. | F25: Oui | G25: OK | H25: 46319 | I25: RAS
A26: 22 | B26: E. SYNC | C26: SYNC | D26: Analyse vidéo et son : un cas avec TC, si possible un cas avec seulement du LTC sur une piste audio. | E26: Paires trouvées et calées (noter les cas non trouvés). | F26: Non
A27: 23 | B27: E. SYNC | C27: 20 | D27: Ouvrir le détail d'une paire, faire défiler la colonne de gauche. | E27: Seule la colonne de gauche défile ; l'explorateur ne bouge pas. | F27: Oui | G27: Partiel | H27: 46321 | I27: Si j'ai bien compris : j'ai importé plusieurs rushes vidéo et plusieurs audio dans l'onglet SYNC, quand je déplace la souris sur une colonne et j'utilise la molette, seule la colonne que je survole défile (Explorer, Vidéo ou Audio). Par contre, j'ai remarqué que "Vidéo" et "Audio" sont écrit tout à gauche, il faudrait que chacun soit au dessus de sa colonne (voir capture) | J27: Oui, c'est le bon protocole : test OK pour le défilement. Titres « Vidéos » et « Sons » au-dessus de chaque liste : fait. À revoir avec le build du 27/10 (run 40517638115).
A28: 24 | B28: E. SYNC | C28: 23 | D28: Re-wrap « Dans un dossier ». | E28: Fichiers _sync créés dans le dossier choisi. | F28: Oui | G28: KO | H28: 46321 | I28: Il manque des réglages dans la partie droite (voir captures) | J28: Corrigé : la destination et les options d'export sont visibles dès le départ (bouton actif après l'analyse). À refaire avec le build du 27/10 (run 40517638115).
A29: 25 | B29: E. SYNC | C29: 27 | D29: Passer l'interface en anglais (Préférences > Général > Langue). | E29: Remarques des paires affichées en anglais. | F29: Oui | G29: OK | H29: 46319 | I29: RAS
A30: 26 | B30: F. TRANSCODE | C30: 28 | D30: 1. Resolve : titre (texte blanc) sur une timeline vide. 2. Deliver : QuickTime, Apple ProRes 4444, « Export Alpha » coché. 3. TRANSCODE : ajouter ce fichier, préréglage ProRes 4444, lancer. 4. Refaire avec le préréglage PNG. 5. Réimporter les deux dans Resolve, au-dessus d'une image. | E30: Le texte est détouré sur l'image (fond transparent). Fond noir = transparence perdue. | F30: Oui | G30: OK | H30: 46321 | I30: RAS | J30: Test réécrit pas à pas (colonne Action).
A31: 27 | B31: F. TRANSCODE | C31: 36 | D31: 1. TRANSCODE > Incrustations : « Créer des sous-titres », saisir deux sous-titres, enregistrer en ASS. 2. Rouvrir ce fichier avec « Éditer », corriger un texte et un temps, enregistrer. 3. Cocher l'incrustation de ce fichier sur une vidéo et lancer. 4. (Si Aegisub) ouvrir le fichier. | E31: Corrections conservées à la réouverture ; sous-titres visibles à l'image aux bons temps ; styles intacts dans Aegisub. | F31: Oui | G31: OK | H31: 46321 | I31: RAS | J31: Test réécrit pas à pas (colonne Action).
A32: 28 | B32: G. Fin : données et désinstallation | C32: 24 | D32: Préférences > Général > liste « À l'ouverture de VERIFLOW » : choisir « Repartir à zéro ». Fermer puis rouvrir VERIFLOW. | E32: État de travail vide (destinations, dossiers dépliés) ; langue et favoris conservés. | F32: Oui | G32: OK | H32: 46321 | I32: Garder tout de même le réglage par défaut de l'applicaiton qui s'ouvre en grande fenêtre ajustée à l'écran. (voir test 4) | J32: L'option est dans la liste déroulante « À l'ouverture de VERIFLOW » (Préférences > Général), au-dessus des deux boutons. À refaire.
A33: 29 | B33: G. Fin : données et désinstallation | C33: 24 | D33: Désinstaller par Paramètres > Applications, case « Supprimer les données de l'application » cochée ; réinstaller. | E33: Plus aucune destination OFFLOAD. | F33: Oui | G33: OK | H33: 46321 | I33: RAS | J33: Corrigé : installation dans C:\Program Files\VERIFLOW (droits administrateur demandés). Désinstalle d'abord l'ancienne version (AppData). À refaire avec le build du 24/10 (run 40104706786).
A34: 30 | B34: B. OFFLOAD | C34: 21 | D34: Explorateur : cliquer sur le bouton ⏏ à côté d'un disque externe ou d'une carte. | E34: Barre d'état : « Éjecté, tu peux le débrancher ». Le disque disparaît de l'explorateur. En cas de refus, le message donne la raison de Windows. | F34: Oui | G34: KO | H34: 46321 | I34: ejection impossible (voir capture) | J34: La capture de l'éjection n'est pas arrivée (5 captures reçues : SYNC, lecteur rapide). Recopie le message de la barre d'état en bas ici, ou renvoie la capture.
A35: 31 | B35: B. OFFLOAD | C35: 21 | D35: Explorateur : déplier le disque HERVE EDU (F:). | E35: Les dossiers FOUND.000 à FOUND.004 n'apparaissent plus. | F35: Oui | G35: OK | H35: 46321 | I35: RAS | J35: Nouveau test (correctifs du 24/10).
A36: 32 | B36: D. PLAYER | C36: 38 | D36: PLAYER en mode AUDIO : cliquer SOLO puis MUTE sur une piste. | E36: SOLO en orange, MUTE en rouge quand ils sont actifs. | F36: Oui | G36: Partiel | H36: 46321 | I36: Ok pour les mise en couleur mais : le bouton MUTE doit être prioritaire sur le bouton SOLO, si une piste est en MUTE et en SOLO, alors elle est MUTE. Il faut aussi ajouter un bouton SOLO pour chaque piste de la console du mode VIDEO. | J36: Corrigé : MUTE prime sur SOLO ; bouton S ajouté sur chaque piste en mode VIDEO. Voir test 38 (build du 27/10 (run 40517638115)).
A37: 33 | B37: A. Installation et menus | C37: 38 | D37: Ouvrir un projet et regarder la barre du haut. | E37: Nom du projet au centre de la fenêtre. | F37: Oui | G37: OK | H37: 46321 | I37: RAS | J37: Nouveau test (correctifs du 24/10).
A38: 34 | B38: C. MEDIA et second écran | C38: 38 | D38: MEDIA : modifier un champ, puis Entrée (clavier principal), puis un autre avec Entrée du pavé numérique. Regarder la barre Enregistrer et la colonne TC en mode AUDIO. | E38: Enregistré à chaque Entrée ; barre Enregistrer sur toute la largeur, séparée des champs ; TC affiché pour les WAV. | F38: Oui | G38: OK | H38: 46321 | I38: RAS | J38: Nouveau test (correctifs du 24/10).
A39: 35 | B39: E. SYNC | C39: 27 | D39: SYNC : un rush vidéo avec LTC sur une piste et son témoin sur l'autre, avec son WAV. Méthode Automatique, Analyser. | E39: Colonne Méthode : LTC ; badge LTC à côté du timecode ; TC = celui du LTC (pas l'horloge de la Panasonic). | F39: Non | J39: Nouveau test (correctifs du 24/10).
A40: 36 | B40: E. SYNC | C40: 27 | D40: SYNC : tous les rushes Panasonic sans LTC et tous les sons (tests compris), méthode Automatique. | E40: Bon son pour chaque plan ; remarque « timecode sans rapport avec le son : son retrouvé par la forme d'onde » ; les sons de test restent non utilisés (mode AUDIO). | F40: Non | J40: Nouveau test (correctifs du 24/10).
A41: 37 | B41: E. SYNC | C41: 27 | D41: SYNC : créer les fichiers synchronisés (option « une piste mono par canal » cochée par défaut), puis les ouvrir dans Premiere. | E41: Image présente ; 6 pistes mono de l'enregistreur + pistes caméra ; son calé sur le clap. | F41: Non | J41: Nouveau test (correctifs du 24/10).
...

Sheet Synthèse
A1: Synthèse (calculée automatiquement depuis l'onglet Tests)
A3: PR | B3: Tests | C3: Effectués | D3: OK | E3: KO | F3: Partiel | G3: Non testable | H3: Statut
A4: 17 | B4: =COUNTIF(Tests!$C$5:$C$54,"*"&A4&"*") | C4: =COUNTIFS(Tests!$C$5:$C$54,"*"&A4&"*",Tests!$F$5:$F$54,"Oui") | D4: =COUNTIFS(Tests!$C$5:$C$54,"*"&A4&"*",Tests!$G$5:$G$54,"OK") | E4: =COUNTIFS(Tests!$C$5:$C$54,"*"&A4&"*",Tests!$G$5:$G$54,"KO") | F4: =COUNTIFS(Tests!$C$5:$C$54,"*"&A4&"*",Tests!$G$5:$G$54,"Partiel") | G4: =COUNTIFS(Tests!$C$5:$C$54,"*"&A4&"*",Tests!$G$5:$G$54,"Non testable") | H4: =IF(E4>0,"À corriger",IF(D4+G4=B4,"Validée",IF(C4=0,"À tester","En cours")))
A5: 20 | B5: =COUNTIF(Tests!$C$5:$C$54,"*"&A5&"*") | C5: =COUNTIFS(Tests!$C$5:$C$54,"*"&A5&"*",Tests!$F$5:$F$54,"Oui") | D5: =COUNTIFS(Tests!$C$5:$C$54,"*"&A5&"*",Tests!$G$5:$G$54,"OK") | E5: =COUNTIFS(Tests!$C$5:$C$54,"*"&A5&"*",Tests!$G$5:$G$54,"KO") | F5: =COUNTIFS(Tests!$C$5:$C$54,"*"&A5&"*",Tests!$G$5:$G$54,"Partiel") | G5: =COUNTIFS(Tests!$C$5:$C$54,"*"&A5&"*",Tests!$G$5:$G$54,"Non testable") | H5: =IF(E5>0,"À corriger",IF(D5+G5=B5,"Validée",IF(C5=0,"À tester","En cours")))
A6: 21 | B6: =COUNTIF(Tests!$C$5:$C$54,"*"&A6&"*") | C6: =COUNTIFS(Tests!$C$5:$C$54,"*"&A6&"*",Tests!$F$5:$F$54,"Oui") | D6: =COUNTIFS(Tests!$C$5:$C$54,"*"&A6&"*",Tests!$G$5:$G$54,"OK") | E6: =COUNTIFS(Tests!$C$5:$C$54,"*"&A6&"*",Tests!$G$5:$G$54,"KO") | F6: =COUNTIFS(Tests!$C$5:$C$54,"*"&A6&"*",Tests!$G$5:$G$54,"Partiel") | G6: =COUNTIFS(Tests!$C$5:$C$54,"*"&A6&"*",Tests!$G$5:$G$54,"Non testable") | H6: =IF(E6>0,"À corriger",IF(D6+G6=B6,"Validée",IF(C6=0,"À tester","En cours")))
A7: 23 | B7: =COUNTIF(Tests!$C$5:$C$54,"*"&A7&"*") | C7: =COUNTIFS(Tests!$C$5:$C$54,"*"&A7&"*",Tests!$F$5:$F$54,"Oui") | D7: =COUNTIFS(Tests!$C$5:$C$54,"*"&A7&"*",Tests!$G$5:$G$54,"OK") | E7: =COUNTIFS(Tests!$C$5:$C$54,"*"&A7&"*",Tests!$G$5:$G$54,"KO") | F7: =COUNTIFS(Tests!$C$5:$C$54,"*"&A7&"*",Tests!$G$5:$G$54,"Partiel") | G7: =COUNTIFS(Tests!$C$5:$C$54,"*"&A7&"*",Tests!$G$5:$G$54,"Non testable") | H7: =IF(E7>0,"À corriger",IF(D7+G7=B7,"Validée",IF(C7=0,"À tester","En cours")))
A8: 24 | B8: =COUNTIF(Tests!$C$5:$C$54,"*"&A8&"*") | C8: =COUNTIFS(Tests!$C$5:$C$54,"*"&A8&"*",Tests!$F$5:$F$54,"Oui") | D8: =COUNTIFS(Tests!$C$5:$C$54,"*"&A8&"*",Tests!$G$5:$G$54,"OK") | E8: =COUNTIFS(Tests!$C$5:$C$54,"*"&A8&"*",Tests!$G$5:$G$54,"KO") | F8: =COUNTIFS(Tests!$C$5:$C$54,"*"&A8&"*",Tests!$G$5:$G$54,"Partiel") | G8: =COUNTIFS(Tests!$C$5:$C$54,"*"&A8&"*",Tests!$G$5:$G$54,"Non testable") | H8: =IF(E8>0,"À corriger",IF(D8+G8=B8,"Validée",IF(C8=0,"À tester","En cours")))
A9: 25 | B9: =COUNTIF(Tests!$C$5:$C$54,"*"&A9&"*") | C9: =COUNTIFS(Tests!$C$5:$C$54,"*"&A9&"*",Tests!$F$5:$F$54,"Oui") | D9: =COUNTIFS(Tests!$C$5:$C$54,"*"&A9&"*",Tests!$G$5:$G$54,"OK") | E9: =COUNTIFS(Tests!$C$5:$C$54,"*"&A9&"*",Tests!$G$5:$G$54,"KO") | F9: =COUNTIFS(Tests!$C$5:$C$54,"*"&A9&"*",Tests!$G$5:$G$54,"Partiel") | G9: =COUNTIFS(Tests!$C$5:$C$54,"*"&A9&"*",Tests!$G$5:$G$54,"Non testable") | H9: =IF(E9>0,"À corriger",IF(D9+G9=B9,"Validée",IF(C9=0,"À tester","En cours")))
A10: 26 | B10: =COUNTIF(Tests!$C$5:$C$54,"*"&A10&"*") | C10: =COUNTIFS(Tests!$C$5:$C$54,"*"&A10&"*",Tests!$F$5:$F$54,"Oui") | D10: =COUNTIFS(Tests!$C$5:$C$54,"*"&A10&"*",Tests!$G$5:$G$54,"OK") | E10: =COUNTIFS(Tests!$C$5:$C$54,"*"&A10&"*",Tests!$G$5:$G$54,"KO") | F10: =COUNTIFS(Tests!$C$5:$C$54,"*"&A10&"*",Tests!$G$5:$G$54,"Partiel") | G10: =COUNTIFS(Tests!$C$5:$C$54,"*"&A10&"*",Tests!$G$5:$G$54,"Non testable") | H10: =IF(E10>0,"À corriger",IF(D10+G10=B10,"Validée",IF(C10=0,"À tester","En cours")))
A11: 27 | B11: =COUNTIF(Tests!$C$5:$C$54,"*"&A11&"*") | C11: =COUNTIFS(Tests!$C$5:$C$54,"*"&A11&"*",Tests!$F$5:$F$54,"Oui") | D11: =COUNTIFS(Tests!$C$5:$C$54,"*"&A11&"*",Tests!$G$5:$G$54,"OK") | E11: =COUNTIFS(Tests!$C$5:$C$54,"*"&A11&"*",Tests!$G$5:$G$54,"KO") | F11: =COUNTIFS(Tests!$C$5:$C$54,"*"&A11&"*",Tests!$G$5:$G$54,"Partiel") | G11: =COUNTIFS(Tests!$C$5:$C$54,"*"&A11&"*",Tests!$G$5:$G$54,"Non testable") | H11: =IF(E11>0,"À corriger",IF(D11+G11=B11,"Validée",IF(C11=0,"À tester","En cours")))
A12: 28 | B12: =COUNTIF(Tests!$C$5:$C$54,"*"&A12&"*") | C12: =COUNTIFS(Tests!$C$5:$C$54,"*"&A12&"*",Tests!$F$5:$F$54,"Oui") | D12: =COUNTIFS(Tests!$C$5:$C$54,"*"&A12&"*",Tests!$G$5:$G$54,"OK") | E12: =COUNTIFS(Tests!$C$5:$C$54,"*"&A12&"*",Tests!$G$5:$G$54,"KO") | F12: =COUNTIFS(Tests!$C$5:$C$54,"*"&A12&"*",Tests!$G$5:$G$54,"Partiel") | G12: =COUNTIFS(Tests!$C$5:$C$54,"*"&A12&"*",Tests!$G$5:$G$54,"Non testable") | H12: =IF(E12>0,"À corriger",IF(D12+G12=B12,"Validée",IF(C12=0,"À tester","En cours")))
A13: 29 | B13: =COUNTIF(Tests!$C$5:$C$54,"*"&A13&"*") | C13: =COUNTIFS(Tests!$C$5:$C$54,"*"&A13&"*",Tests!$F$5:$F$54,"Oui") | D13: =COUNTIFS(Tests!$C$5:$C$54,"*"&A13&"*",Tests!$G$5:$G$54,"OK") | E13: =COUNTIFS(Tests!$C$5:$C$54,"*"&A13&"*",Tests!$G$5:$G$54,"KO") | F13: =COUNTIFS(Tests!$C$5:$C$54,"*"&A13&"*",Tests!$G$5:$G$54,"Partiel") | G13: =COUNTIFS(Tests!$C$5:$C$54,"*"&A13&"*",Tests!$G$5:$G$54,"Non testable") | H13: =IF(E13>0,"À corriger",IF(D13+G13=B13,"Validée",IF(C13=0,"À tester","En cours")))
A14: 30 | B14: =COUNTIF(Tests!$C$5:$C$54,"*"&A14&"*") | C14: =COUNTIFS(Tests!$C$5:$C$54,"*"&A14&"*",Tests!$F$5:$F$54,"Oui") | D14: =COUNTIFS(Tests!$C$5:$C$54,"*"&A14&"*",Tests!$G$5:$G$54,"OK") | E14: =COUNTIFS(Tests!$C$5:$C$54,"*"&A14&"*",Tests!$G$5:$G$54,"KO") | F14: =COUNTIFS(Tests!$C$5:$C$54,"*"&A14&"*",Tests!$G$5:$G$54,"Partiel") | G14: =COUNTIFS(Tests!$C$5:$C$54,"*"&A14&"*",Tests!$G$5:$G$54,"Non testable") | H14: =IF(E14>0,"À corriger",IF(D14+G14=B14,"Validée",IF(C14=0,"À tester","En cours")))
A15: 31 | B15: =COUNTIF(Tests!$C$5:$C$54,"*"&A15&"*") | C15: =COUNTIFS(Tests!$C$5:$C$54,"*"&A15&"*",Tests!$F$5:$F$54,"Oui") | D15: =COUNTIFS(Tests!$C$5:$C$54,"*"&A15&"*",Tests!$G$5:$G$54,"OK") | E15: =COUNTIFS(Tests!$C$5:$C$54,"*"&A15&"*",Tests!$G$5:$G$54,"KO") | F15: =COUNTIFS(Tests!$C$5:$C$54,"*"&A15&"*",Tests!$G$5:$G$54,"Partiel") | G15: =COUNTIFS(Tests!$C$5:$C$54,"*"&A15&"*",Tests!$G$5:$G$54,"Non testable") | H15: =IF(E15>0,"À corriger",IF(D15+G15=B15,"Validée",IF(C15=0,"À tester","En cours")))
... A24: 41 | B24: =COUNTIF(Tests!$C$5:$C$54,"*"&A24&"*") | C24: =COUNTIFS(Tests!$C$5:$C$54,"*"&A24&"*",Tests!$F$5:$F$54,"Oui") | D24: =COUNTIFS(Tests!$C$5:$C$54,"*"&A24&"*",Tests!$G$5:$G$54,"OK") | E24: =COUNTIFS(Tests!$C$5:$C$54,"*"&A24&"*",Tests!$G$5:$G$54,"KO") | F24: =COUNTIFS(Tests!$C$5:$C$54,"*"&A24&"*",Tests!$G$5:$G$54,"Partiel") | G24: =COUNTIFS(Tests!$C$5:$C$54,"*"&A24&"*",Tests!$G$5:$G$54,"Non testable") | H24: =IF(E24>0,"À corriger",IF(D24+G24=B24,"Validée",IF(C24=0,"À tester","En cours")))
A25: 5 (en attente) | B25: =COUNTIF(Tests!$C$5:$C$54,A25) | C25: =COUNTIFS(Tests!$C$5:$C$54,A25,Tests!$F$5:$F$54,"Oui") | D25: =COUNTIFS(Tests!$C$5:$C$54,A25,Tests!$G$5:$G$54,"OK") | E25: =COUNTIFS(Tests!$C$5:$C$54,A25,Tests!$G$5:$G$54,"KO") | F25: =COUNTIFS(Tests!$C$5:$C$54,A25,Tests!$G$5:$G$54,"Partiel") | G25: =COUNTIFS(Tests!$C$5:$C$54,A25,Tests!$G$5:$G$54,"Non testable") | H25: =IF(E25>0,"À corriger",IF(D25+G25=B25,"Validée",IF(C25=0,"À tester","En cours")))
A26: SYNC | B26: =COUNTIF(Tests!$C$5:$C$54,A26) | C26: =COUNTIFS(Tests!$C$5:$C$54,A26,Tests!$F$5:$F$54,"Oui") | D26: =COUNTIFS(Tests!$C$5:$C$54,A26,Tests!$G$5:$G$54,"OK") | E26: =COUNTIFS(Tests!$C$5:$C$54,A26,Tests!$G$5:$G$54,"KO") | F26: =COUNTIFS(Tests!$C$5:$C$54,A26,Tests!$G$5:$G$54,"Partiel") | G26: =COUNTIFS(Tests!$C$5:$C$54,A26,Tests!$G$5:$G$54,"Non testable") | H26: =IF(E26>0,"À corriger",IF(D26+G26=B26,"Validée",IF(C26=0,"À tester","En cours")))
A27: Total | B27: =COUNTA(Tests!$A$5:$A$54) | C27: =COUNTIF(Tests!$F$5:$F$54,"Oui") | D27: =COUNTIF(Tests!$G$5:$G$54,"OK") | E27: =COUNTIF(Tests!$G$5:$G$54,"KO") | F27: =COUNTIF(Tests!$G$5:$G$54,"Partiel") | G27: =COUNTIF(Tests!$G$5:$G$54,"Non testable")
A29: Un test peut couvrir plusieurs PR : il compte pour chacune. « Validée » = tous les tests de la PR en OK ou Non testable. Un test « Partiel » corrigé depuis reste « En cours » jusqu'à ce que tu le refasses.

Sheet Légende
A1: Mode d'emploi
A2: Cellules à remplir | B2: Colonnes jaunes de l'onglet Tests : Effectué, Résultat, Date, Commentaires. Le reste est fixe.
A3: Effectué | B3: Oui ou Non (liste déroulante).
A4: Résultat | B4: OK : conforme au résultat attendu. KO : non conforme. Partiel : en partie conforme (préciser). Non testable : matériel ou fichier absent.
A5: Date | B5: Date du test, format JJ/MM/AAAA.
A6: Commentaires | B6: Pour un KO ou un Partiel : ce qui s'est passé, le message affiché, le fichier utilisé (format, caméra, codec).
A7: Ordre | B7: Suivre l'ordre des numéros. La section G (désinstallation) efface les réglages : la faire en dernier.
A8: Build | B8: https://github.com/Herve-obe/VERIFLOW-v4/actions/runs/41209261957 (artefact veriflow-windows-latest, build du 31/10).
A9: Retour | B9: Déposer le fichier rempli dans la conversation, ou le pousser dans docs/recette/ du dépôt.
A11: Exemple de ligne remplie
A12: N° | B12: PR | C12: Effectué | D12: Résultat | E12: Date | F12: Commentaires
A13: 13 | B13: 21 | C13: Oui | D13: KO | E13: 21/10/2026 | F13: Fichier ouvert dans Reaper : message affiché, mais le disque a disparu de l'explorateur.
